2025-05-15 18:01:05,485 - root - INFO - 使用的 ChromeDriver 路径: D:\gmj\workSpaces\workSpaces_pycharm\autoTest4\Base\utils\chromedriver.exe
2025-05-15 18:01:05,615 - root - INFO - Test case test_add_sales_plan started at 2025-05-15 18:01:05.615767
2025-05-15 18:01:06,642 - root - INFO - 开始登录操作
2025-05-15 18:03:06,645 - root - ERROR - 登录过程中出现错误: HTTPConnectionPool(host='localhost', port=59289): Read timed out. (read timeout=120)
Traceback (most recent call last):
  File "D:\gmj\workSpaces\workSpaces_pycharm\autoTest4\.venv\Lib\site-packages\urllib3\connectionpool.py", line 534, in _make_request
    response = conn.getresponse()
               ^^^^^^^^^^^^^^^^^^
  File "D:\gmj\workSpaces\workSpaces_pycharm\autoTest4\.venv\Lib\site-packages\urllib3\connection.py", line 516, in getresponse
    httplib_response = super().getresponse()
                       ^^^^^^^^^^^^^^^^^^^^^
  File "D:\software\python3.12\Lib\http\client.py", line 1428, in getresponse
    response.begin()
  File "D:\software\python3.12\Lib\http\client.py", line 331, in begin
    version, status, reason = self._read_status()
                              ^^^^^^^^^^^^^^^^^^^
  File "D:\software\python3.12\Lib\http\client.py", line 292, in _read_status
    line = str(self.fp.readline(_MAXLINE + 1), "iso-8859-1")
               ^^^^^^^^^^^^^^^^^^^^^^^^^^^^^^
  File "D:\software\python3.12\Lib\socket.py", line 707, in readinto
    return self._sock.recv_into(b)
           ^^^^^^^^^^^^^^^^^^^^^^^
TimeoutError: timed out

The above exception was the direct cause of the following exception:

Traceback (most recent call last):
  File "D:\gmj\workSpaces\workSpaces_pycharm\autoTest4\PageObject\login_page.py", line 142, in login
    self.driver.get(ERP_URL)
  File "D:\gmj\workSpaces\workSpaces_pycharm\autoTest4\.venv\Lib\site-packages\selenium\webdriver\remote\webdriver.py", line 473, in get
    self.execute(Command.GET, {"url": url})
  File "D:\gmj\workSpaces\workSpaces_pycharm\autoTest4\.venv\Lib\site-packages\selenium\webdriver\remote\webdriver.py", line 446, in execute
    response = self.command_executor.execute(driver_command, params)
               ^^^^^^^^^^^^^^^^^^^^^^^^^^^^^^^^^^^^^^^^^^^^^^^^^^^^^
  File "D:\gmj\workSpaces\workSpaces_pycharm\autoTest4\.venv\Lib\site-packages\selenium\webdriver\remote\remote_connection.py", line 404, in execute
    return self._request(command_info[0], url, body=data)
           ^^^^^^^^^^^^^^^^^^^^^^^^^^^^^^^^^^^^^^^^^^^^^^
  File "D:\gmj\workSpaces\workSpaces_pycharm\autoTest4\.venv\Lib\site-packages\selenium\webdriver\remote\remote_connection.py", line 428, in _request
    response = self._conn.request(method, url, body=body, headers=headers, timeout=self._client_config.timeout)
               ^^^^^^^^^^^^^^^^^^^^^^^^^^^^^^^^^^^^^^^^^^^^^^^^^^^^^^^^^^^^^^^^^^^^^^^^^^^^^^^^^^^^^^^^^^^^^^^^
  File "D:\gmj\workSpaces\workSpaces_pycharm\autoTest4\.venv\Lib\site-packages\urllib3\_request_methods.py", line 143, in request
    return self.request_encode_body(
           ^^^^^^^^^^^^^^^^^^^^^^^^^
  File "D:\gmj\workSpaces\workSpaces_pycharm\autoTest4\.venv\Lib\site-packages\urllib3\_request_methods.py", line 278, in request_encode_body
    return self.urlopen(method, url, **extra_kw)
           ^^^^^^^^^^^^^^^^^^^^^^^^^^^^^^^^^^^^^
  File "D:\gmj\workSpaces\workSpaces_pycharm\autoTest4\.venv\Lib\site-packages\urllib3\poolmanager.py", line 443, in urlopen
    response = conn.urlopen(method, u.request_uri, **kw)
               ^^^^^^^^^^^^^^^^^^^^^^^^^^^^^^^^^^^^^^^^^
  File "D:\gmj\workSpaces\workSpaces_pycharm\autoTest4\.venv\Lib\site-packages\urllib3\connectionpool.py", line 841, in urlopen
    retries = retries.increment(
              ^^^^^^^^^^^^^^^^^^
  File "D:\gmj\workSpaces\workSpaces_pycharm\autoTest4\.venv\Lib\site-packages\urllib3\util\retry.py", line 474, in increment
    raise reraise(type(error), error, _stacktrace)
          ^^^^^^^^^^^^^^^^^^^^^^^^^^^^^^^^^^^^^^^^
  File "D:\gmj\workSpaces\workSpaces_pycharm\autoTest4\.venv\Lib\site-packages\urllib3\util\util.py", line 39, in reraise
    raise value
  File "D:\gmj\workSpaces\workSpaces_pycharm\autoTest4\.venv\Lib\site-packages\urllib3\connectionpool.py", line 787, in urlopen
    response = self._make_request(
               ^^^^^^^^^^^^^^^^^^^
  File "D:\gmj\workSpaces\workSpaces_pycharm\autoTest4\.venv\Lib\site-packages\urllib3\connectionpool.py", line 536, in _make_request
    self._raise_timeout(err=e, url=url, timeout_value=read_timeout)
  File "D:\gmj\workSpaces\workSpaces_pycharm\autoTest4\.venv\Lib\site-packages\urllib3\connectionpool.py", line 367, in _raise_timeout
    raise ReadTimeoutError(
urllib3.exceptions.ReadTimeoutError: HTTPConnectionPool(host='localhost', port=59289): Read timed out. (read timeout=120)
2025-05-15 18:03:06,680 - root - INFO - 开始登录操作
2025-05-15 18:03:59,345 - root - INFO - 已打开登录页面
2025-05-15 18:03:59,476 - root - INFO - 已输入用户名：guomj
2025-05-15 18:03:59,556 - root - INFO - 已输入密码：gmj123..
2025-05-15 18:03:59,670 - root - INFO - 验证码图片已保存到 D:\gmj\workSpaces\workSpaces_pycharm\autoTest4\Base\utils\captcha.png
2025-05-15 18:04:01,168 - root - INFO - 验证码识别结果: 404
2025-05-15 18:04:01,246 - root - INFO - 已输入验证码: 404，第 2 次尝试
2025-05-15 18:04:06,309 - root - WARNING - 第 2 次登录失败，重新尝试
2025-05-15 18:04:06,309 - root - INFO - 开始登录操作
2025-05-15 18:04:06,732 - root - INFO - 已打开登录页面
2025-05-15 18:04:06,996 - root - INFO - 已输入用户名：guomj
2025-05-15 18:04:07,080 - root - INFO - 已输入密码：gmj123..
2025-05-15 18:04:07,193 - root - INFO - 验证码图片已保存到 D:\gmj\workSpaces\workSpaces_pycharm\autoTest4\Base\utils\captcha.png
2025-05-15 18:04:09,759 - root - INFO - 验证码识别结果: MrTK
2025-05-15 18:04:09,828 - root - INFO - 已输入验证码: MrTK，第 3 次尝试
2025-05-15 18:04:11,851 - root - INFO - 登录成功
2025-05-15 18:04:12,790 - root - INFO - 准备添加销售计划，ASIN=B0BTHRCY23, 月份数据=[{'month': '五月', 'value': '1000'}, {'month': '六月', 'value': '1000'}, {'month': '七月', 'value': '1000'}, {'month': '八月', 'value': '1000'}]
2025-05-15 18:04:15,680 - root - INFO - 点击前
2025-05-15 18:04:18,295 - root - INFO - 点击后
2025-05-15 18:04:28,381 - root - INFO - 关闭浏览器
2025-05-15 18:04:30,475 - root - INFO - Test case test_add_sales_plan ended at 2025-05-15 18:04:30.475275
